Workbook

Sheet Variables
A1: Givens (Max) | B1: value | C1: unit | D1: Conversion | E1: unit | I1: Input Variables
A2: Lt (total handpiece length) | B2: 122 | C2: mm | D2: =B2/25.4 -> 4.8031496 | E2: in | I2: Variable | J2: Symbol | K2: Value | L2: units | M2: Unit conversion | N2: Units | O2: Equation
A3: dh (head diameter) | B3: 22 | C3: mm | D3: =B3/25.4 -> 0.86614173 | E3: in | I3: Diametral pitch | J3: P | K3: 40 | L3: teeth/in
A4: hL (head height) | B4: 26 | C4: mm | D4: =B4/25.4 -> 1.023622 | E4: in | I4: Face width | J4: F | K4: =10/K3 -> 0.25 | L4: in | O4: 10/P (table 13-3)
A5: d (handpiece body diameter) | B5: 20 | C5: mm | D5: =B5/25.4 -> 0.78740157 | E5: in | I5: Pinion tooth | J5: Np = N2 | K5: 32 | L5: teeth
A6: L (handpiece body length) | B6: 100 | C6: mm | D6: =B6/25.4 -> 3.9370079 | E6: in | I6: Gear tooth | J6: Ng = N3 | K6: 32 | L6: teeth
A7: Lm (Motor input shaft length) | B7: 25 | C7: mm | D7: =B7/25.4 -> 0.98425197 | E7: in | I7: Pressure angle | J7: Φp | K7: 20 | L7: degrees | M7: =K7*(pi()/180) -> 0.34906585 | N7: rad
A8: dm (motor input shaft diameter) | B8: 7 | C8: mm | D8: =B8/25.4 -> 0.27559055 | E8: in | I8: Input Max Power | J8: Hmax | K8: =D9*B10/100 -> 62.831853 | L8: N*m/s | M8: =B9*D10*2*pi()/33000 -> 0.084258657 | N8: hp
A9: ωmax (motor input speed) | B9: 30000 | C9: rpm | D9: =B9*2*pi()/60 -> 3141.5927 | E9: rad/s | I9: Gear train ratio | J9: e | K9: =K5/K6 -> 1
A10: Tmax (motor input torque) | B10: 2 | C10: N*cm | D10: =(B10/100)*0.73756 -> 0.0147512 | E10: ft*lbf | I10: Output speed | J10: ωo=ω3 | K10: 30000 | L10: rpm | M10: =D10 -> 0.0147512 | N10: rad/s
I11: Gear ratio | J11: e | K11: 1
I12: Quality number | J12: Qv | K12: 11
I13: Gear ratio | J13: mG | K13: =K6/K5 -> 1
A14: Givens (Exact) | B14: value | C14: unit | D14: Conversion | E14: unit | I14: Reliability | J14: R | K14: 0.99
A15: Dc (bur cutting surface diameter) | B15: 2 | C15: mm | D15: =B15/25.4 -> 0.078740157 | E15: in | I15: Life cycle of the pinion | J15: NL | K15: 10000000
A16: Lc (bur cutting surface length) | B16: 4 | C16: mm | D16: =B16/25.4 -> 0.15748032 | E16: in | I16: Brinell Hardness (gear) | J16: HB | K16: 248 | O16: Table A-20
A17: Db (bur shaft diameter) | B17: 1.6 | C17: mm | D17: =B17/25.4 -> 0.062992126 | E17: in | I17: distance between bearing B and A (center-to-center distance) | J17: LBA | K17: 0.1 | L17: in
A18: Lb (bur total length) | B18: 26 | C18: mm | D18: =B18/25.4 -> 1.023622 | E18: in | I18: distance between bearing A and pinon (center-center distance) | J18: LAP | K18: 0.1 | L18: in
A19: Safety Factor | B19: 2 | I19: distance between bearing D and gear (center to center distance) | J19: LDG | K19: 0.25 | L19: in
I20: distance between bearing C and gear (center-center distance) | J20: LCG | K20: 0.25 | L20: in
I21: Bearing thickness | J21: B | K21: 0.11 | L21: in
A22: Literature values | B22: value range | D22: unit | E22: Conversion | G22: unit
A23: ωo (low output speed) | B23: 16000 | C23: 18000 | D23: rpm | E23: =B23*2*pi()/60 -> 1675.5161 | F23: =C23*2*pi()/60 -> 1884.9556 | G23: rads/s | I23: Pitch apex height in headpiece | J23: Hpa | K23: =0.5*D4 -> 0.51181102 | L23: in
I24: (assuming pitch apex is located in the center of the headpiece along the axis of the driven and driving shafts)
J25: =0.5*D3 -> 0.43307087
A26: Formulas/Definitions | F26: omega | G26: rad/s
A27: gear train ratio (e) | B27: e = ω3/ω2 = N2/N3 | F27: n | G27: rpm
A28: N2 | B28: pinon tooth number
A29: N3 | B29: gear tooth number
A30: Power (P) | B30: P=ω*𝜏
A31: Conservation of Power | B31: Pin = Pout = ω2 *𝜏2 =ω3*𝜏3
A32: Transmitted load (Wt) | B32: 𝜏 = d/2 * Wt
B33: Wt = 33000 * H/V
A34: Pitch-line velocity (V) | B34: V = pi *d*n/12
A35: Gear Bending Stress | B35: (St)G = (Wt/F)Pd*Ko*Kv(Ks*Km/Kx*JG)
A36: Gear Contact Stress | B36: (Sc)G = Cp*((Wt/F*dp*I)*Ko*Kv*(Km)G*Cs*Cxc)^.5
A37: Pinion Bending Stress | B37: (St)P = (Wt/F)Pd*Ko*Kv(Ks*Km/Kx*JP)
A38: Pinion Contact Stress | B38: (Sc)P = Cp*((Wt/F*dp*I)*Ko*Kv*(Km)P*Cs*Cxc)^.5

Sheet Torque&Power
F2: Inputs | K2: Torque/Power Calculation Outputs
F3: Variable | G3: Symbol | H3: Value | I3: Units | K3: Variable | L3: Symbol | M3: Value | N3: Units | O3: Textbook Ref | P3: Equation
B4: Metric | F4: Pinion teeth | G4: Np | H4: =Variables!K5 -> 32 | K4: gear train ratio | L4: e | M4: =H13 -> 1 | O4: 13-30 | P4: Np/Ng
B5: Given | C5: values | D5: units | F5: Gear teeth | G5: Ng | H5: =Variables!K6 -> 32 | K5: Input Speed | L5: ω2 | M5: =H16 -> 30000 | N5: =I16 -> rpm | O5: 18-2 | P5: ω3/e
B6: N2 | C6: =T6 | D6: =U6 | F6: Input max speed | G6: ωmax | H6: =Variables!B9 -> 30000 | I6: =Variables!C9 -> rpm | K6: Output Torque | L6: T3 | M6: =H19 -> 0.0147512 | N6: =I19 -> ft*lbf | O6: 18-1 | P6: T2*ω2=T3*ω3
B7: N3 | C7: =T7 | D7: =U7 | F7: Output speed | G7: ω3 | H7: =Variables!K10 -> 30000 | I7: =Variables!L10 -> rpm | K7: Output Power | L7: H3 | M7: =H22 -> 0.084258657 | N7: =I22 -> hp | O7: 13-33 | P7: T3*ω3*2*pi/33000
B8: ω2 | C8: =Variables!D9 -> 3141.5927 | D8: =Variables!E9 -> rad/s | F8: Input max torque | G8: Tmax | H8: =Variables!D10 -> 0.0147512 | I8: =Variables!E10 -> ft*lbf | K8: Input Power | L8: H2 | M8: =H25 -> 0.084258657 | N8: =I25 -> hp | O8: 13-33 | P8: T2*ω2*2*pi/33000
B9: ω3 | C9: =Variables!D9 -> 3141.5927 | D9: =Variables!G23 -> rads/s | F9: Input torque | G9: T2 | H9: =H8 -> 0.0147512 | I9: =I8 -> ft*lbf | K9: % power utilization | M9: =H28 -> 100 | N9: =I28 -> % | P9: H2/Hmax
F10: Input max power | G10: Hmax | H10: =Variables!M8 -> 0.084258657 | I10: =Variables!N8 -> hp
B11: 𝜏in | C11: =Variables!B10/100 -> 0.02 | D11: N*m
B12: Pin | C12: =Variables!B11 | D12: =Variables!C11 | G12: 1. gear train ratio (e = N2/N3=ω3/ω2)
G13: e | H13: =H4/H5 -> 1
B14: 1. gear train ratio (e = N2/N3=ω3/ω2)
B15: e | C15: =C6/C7 -> #DIV/0! | G15: 2. Find ω2 and check ω2<=ω2max
G16: ω2 | H16: =H7/H13 -> 30000 | I16: =I6 -> rpm
B17: 2. Find ω2 and check ω2<=ω2max
B18: n2 | C18: =C9/C15 -> #DIV/0! | D18: =D8 -> rad/s | G18: 3. Calculate T3
G19: T3 | H19: =H9*H16/H7 -> 0.0147512 | I19: =I8 -> ft*lbf
B20: 3. Pin =Pout -> Find 𝜏out from 𝜏in *ω2 = 𝜏out *ω3
B21: 𝜏out | C21: =C11*C18/C9 -> #DIV/0! | G21: 4. Calculate H3
G22: H3 | H22: =H19*H7*2*pi()/33000 -> 0.084258657 | I22: =I10 -> hp
B23: 4. check Pactual < Pmax (P=𝜏*ω)
G24: 5. Calculate H2 and check H2 < Hmax
G25: H2 | H25: =H9*H16*2*pi()/33000 -> 0.084258657 | I25: =I10 -> hp
B27: Pactual | C27: =C21*C9 -> #DIV/0! | D27: =D12 | G27: 5. percent of max power utilized
G28: % utilization | H28: =H25/H10*100 -> 100 | I28: %
B29: 5. percent of max power utilized
B30: % utilization | C30: =C27/C12*100 -> #DIV/0!

Sheet Gear Specifications
A1: Inputs | F1: Geometry Outputs
A2: Variable | B2: Symbol | C2: Value | D2: Units | F2: Variable | G2: Symbol | H2: Value | I2: Units | J2: Equation | K2: Textbook Ref
A3: Pinion teeth | B3: Np | C3: =Variables!K5 -> 32 | F3: Pinion module | G3: m(p) | H3: =H5/C3 -> 0.025 | I3: in | J3: d/Np | K3: Eq 13-2
A4: Gear teeth | B4: Ng | C4: =Variables!K6 -> 32 | F4: Gear module | G4: m(g) | H4: =H6/C4 -> 0.025 | I4: in | J4: d/Ng | K4: Eq 13-2
A5: Face width | B5: F | C5: =Variables!K4 -> 0.25 | D5: in | F5: Pinion Pitch Diameter | G5: d(p) | H5: =C3/C7 -> 0.8 | I5: in | J5: Np/P | K5: Eq 13-1
A6: Torque | B6: T | C6: =Variables!D10 -> 0.0147512 | D6: ft*lb | F6: Gear Pitch Diameter | G6: d(g) | H6: =C4/C7 -> 0.8 | I6: in | J6: Ng/P | K6: Eq 13-1
A7: Diametral Pitch | B7: P | C7: =Variables!K3 -> 40 | D7: teeth/in | F7: Clearance | G7: c | H7: =(0.188/C7)+0.002 -> 0.0067 | I7: in | J7: (0.188/P)+0.002 | K7: Table 13-3
A8: Gear Ratio | B8: e | C8: =Variables!K11 -> 1 | F8: Pinion Circular Pitch | G8: p(p) | H8: =pi()*H3 -> 0.078539816 | I8: in | J8: pi(mp) | K8: Eq 13-4
A9: Pressure Angle | B9: Φp | C9: =Variables!K7 -> 20 | D9: degrees | F9: Gear Circular Pitch | G9: p(g) | H9: =pi()*H4 -> 0.078539816 | I9: in | J9: pi(mg) | K9: Eq 13-4
F10: Addendum | G10: a | H10: =(0.54/C7)+(0.46/(C7*(H16)^2)) -> 0.025 | I10: in | J10: 0.54/P+0.460/P(e90)^2 | K10: Table 13-3
F11: Dedendum | G11: b | H11: =1.157/C7 -> 0.028925 | I11: in | J11: 1.157/P | K11: Table 13-1
F12: Whole depth | G12: ht | H12: =2.157/C7 -> 0.053925 | I12: in | J12: 2.157/P
F13: Pinion Pitch Cone Angle | G13: γ | H13: =ATAN(C3/C4) -> 0.78539816 | I13: rad | J13: tan-1(Np/Ng) | K13: Eq 13-14 | L13: =57.2958*ATAN(C3/C4) -> 45.000016 | M13: degrees
A14: https://www.sdp-si.com/resources/elements-of-metric-gear-technology/page4.php | F14: Gear Pitch Cone Angle | G14: Γ | H14: =ATAN(C4/C3) -> 0.78539816 | I14: rad | J14: tan-1(Ng/Np) | K14: Eq 13-14 | L14: =57.2958*ATAN(C4/C3) -> 45.000016 | M14: degrees
F15: Working depth | G15: hk | H15: =2/C7 -> 0.05 | I15: in | J15: 2/P | K15: Table 13-3
F16: 90 Equivalent Gear Ratio | G16: e90 | H16: =SQRT(C8*(COS(H13)/COS(H14))) -> 1 | I16: in | J16: sqrt(e(cosγ/cosΓ) | K16: Table 13-3
F17: Cone Distance | G17: Ao | H17: =C5/0.3 -> 0.83333333 | I17: in | J17: F/0.3 | K17: Table 13-3
F18: Back Cone Radius | G18: Rb | H18: =H17*tan(H13) -> 0.83333333 | I18: in | J18: Ao*tan(γ)
F19: Addendum Angle | G19: θa | H19: =atan(H10/H17) -> 0.029991005 | I19: rad | J19: tan-1(a/Ao) | K19: SDP Table 8-3 | L19: =57.2958*atan(H10/H17) -> 1.7183586 | M19: degrees
F20: Dedendum Angle | G20: θb | H20: =atan(H11/H17) -> 0.034696071 | I20: rad | J20: tan-1(b/Ao) | K20: SDP Table 8-3 | L20: =57.2958*atan(H11/H17) -> 1.9879391 | M20: degrees
F21: Gear Angular Addendum | G21: Z (g) | H21: =H19*cos(H14) -> 0.021206843 | I21: rad | J21: θacos(Γ) | L21: =57.2958*H21 -> 1.215063 | M21: degrees
F22: Pinion Angular Addendum | G22: Z (p) | H22: =H19*cos(H13) -> 0.021206843 | I22: rad | J22: θacos(γ) | L22: =57.2958*H22 -> 1.215063 | M22: degrees
F23: Gear Face Angle | G23: Af (g) | H23: =H14-H19 -> 0.75540716 | I23: rad | J23: Γ-θa | K23: SDP Table 8-3 | L23: =(H14-H19)*57.2958 -> 43.281657 | M23: degrees
F24: Gear Root/Cutting Angle | G24: Ac (g) | H24: =H14-H20 -> 0.75070209 | I24: rad | J24: Γ-θb | K24: SDP Table 8-3 | L24: =H24*57.2958 -> 43.012077 | M24: degrees
F25: Pinion Face Angle | G25: Af (p) | H25: =H13-H19 -> 0.75540716 | I25: rad | J25: γ-θa | L25: =H25*57.2958 -> 43.281657 | M25: degrees
F26: Pinion Root/Cutting Angle | G26: Ac (p) | H26: =H13-H20 -> 0.75070209 | I26: rad | J26: γ-θb | L26: =H26*57.2958 -> 43.012077 | M26: degrees
F27: Gear Outside Diameter | G27: OD (g) | H27: =H6+(2*H10*cos(H14)) -> 0.83535534 | I27: in | J27: d(g)+2(a)cosΓ | K27: SDP Table 8-3
F28: Pinion Outside Diameter | G28: OD (p) | H28: =H5+(2*H10*cos(H13)) -> 0.83535534 | I28: in | J28: d(p)+2(a)cosγ | K28: SDP Table 8-3
F29: Pinion Pitch Apex to Crown | G29: X(p) | H29: =(H17*cos(H13))-(H10*sin(H13)) -> 0.57157798 | I29: in | J29: Aocosγ-(a)sinγ | K29: SDP Table 8-3
F30: Gear Pitch Apex to Crown | G30: X(g) | H30: =(H17*cos(H14))-(H10*sin(H14)) -> 0.57157798 | I30: in | J30: AocosΓ-(a)sinΓ | K30: SDP Table 8-3
F31: Large end tooth thickness | G31: tt | H31: =0.5*pi()/C7 -> 0.039269908 | I31: in | J31: 0.5pi/P
F32: Pinion small end tooth diameter | G32: td (p) | H32: =2*(H17-C5)*sin(H13) -> 0.82495791 | I32: in | J32: 2*(Ao-F)*sin(γ)
F33: Gear small end tooth diameter | G33: td (g) | H33: =2*(H17-C5)*sin(H14) -> 0.82495791 | I33: in | J33: 2*(Ao-F)*sin(Γ)
F34: Pinion small end tooth thickness | G34: tts (p) | H34: =0.5*pi()/(C3/H32) -> 0.040495027 | I34: in | J34: 0.5pi/(Np/tdp)
F35: Gear small end tooth thickness | G35: tts (g) | H35: =0.5*pi()/(C4/H33) -> 0.040495027 | I35: in | J35: 0.5pi/(Ng/tdg)
F37: SUMMARY | G37: Using AISI 1095 hot rolled steel
F38: Variable | G38: Symbol | H38: Pinion | I38: Gear | J38: Both | K38: Units | L38: Equations
F39: Clearance | G39: c | J39: =H7 -> 0.0067 | K39: in | L39: Table 13-3
F40: Addendum | G40: a | J40: =H10 -> 0.025 | K40: in | L40: Table 13-3
F41: Dedendum | G41: b | J41: =H11 -> 0.028925 | K41: in | L41: Table 13-1
...

Sheet Geometry checks
A1: 18 | V1: Overall Geometry Outputs
A2: Geometry Outputs | H2: Givens (Max) | I2: value | J2: unit | K2: Conversion | L2: unit | P2: 1. Calculate dh check dh < d max | V2: Variable | W2: Symbol | X2: Value | Y2: Units
A3: Variable | B3: Symbol | C3: Value | D3: Units | E3: Equation | F3: Textbook Ref | H3: =Variables!A2 -> Lt (total handpiece length) | I3: 122 | J3: =Variables!C2 -> mm | K3: =Variables!D2 -> 4.8031496 | L3: =Variables!E2 -> in | P3: dh= 2*t+ 2*cb + OD (g) | S3: extra room | V3: dh (head diameter) | W3: dh | X3: =Q4 -> 1.0007097 | Y3: =R4 -> in
A4: ='Gear Specifications'!F3 -> Pinion module | B4: ='Gear Specifications'!G3 -> m(p) | C4: ='Gear Specifications'!H3 -> 0.025 | D4: ='Gear Specifications'!I3 -> in | E4: ='Gear Specifications'!J3 -> d/Np | F4: ='Gear Specifications'!K3 -> Eq 13-2 | H4: =Variables!A3 -> dh (head diameter) | I4: 22 | J4: =Variables!C3 -> mm | K4: =Variables!D3 -> 0.86614173 | L4: =Variables!E3 -> in | P4: dh | Q4: =(2*L25)+(2*L26)+C28 -> 1.0007097 | R4: in | S4: dhmax-dh | T4: =K4-Q4 -> -0.13456794 | U4: in | V4: height of beaing C wall | W4: hbw | X4: =T9 -> 0.011456189 | Y4: =U9 -> in
A5: ='Gear Specifications'!F4 -> Gear module | B5: ='Gear Specifications'!G4 -> m(g) | C5: ='Gear Specifications'!H4 -> 0.025 | D5: ='Gear Specifications'!I4 -> in | E5: ='Gear Specifications'!J4 -> d/Ng | F5: ='Gear Specifications'!K4 -> Eq 13-2 | H5: =Variables!A4 -> hL (head height) | I5: 26 | J5: =Variables!C4 -> mm | K5: =Variables!D4 -> 1.023622 | L5: =Variables!E4 -> in | V5: head height | W5: hL | X5: =Q13 -> 1.0121659 | Y5: in
A6: ='Gear Specifications'!F5 -> Pinion Pitch Diameter | B6: ='Gear Specifications'!G5 -> d(p) | C6: ='Gear Specifications'!H5 -> 0.8 | D6: ='Gear Specifications'!I5 -> in | E6: ='Gear Specifications'!J5 -> Np/P | F6: ='Gear Specifications'!K5 -> Eq 13-1 | H6: =Variables!A5 -> d (handpiece body diameter) | I6: 20 | J6: =Variables!C5 -> mm | K6: =Variables!D5 -> 0.78740157 | L6: =Variables!E5 -> in | V6: handpiece body diameter | W6: d | X6: =Q20 -> 0.44094488 | Y6: in
A7: ='Gear Specifications'!F6 -> Gear Pitch Diameter | B7: ='Gear Specifications'!G6 -> d(g) | C7: ='Gear Specifications'!H6 -> 0.8 | D7: ='Gear Specifications'!I6 -> in | E7: ='Gear Specifications'!J6 -> Ng/P | F7: ='Gear Specifications'!K6 -> Eq 13-1 | H7: =Variables!A6 -> L (handpiece body length) | I7: 100 | J7: =Variables!C6 -> mm | K7: =Variables!D6 -> 3.9370079 | L7: =Variables!E6 -> in | P7: 2. Calculate hL without hbw & check hL< hL max solve for left over room | X7: =Q21
A8: ='Gear Specifications'!F7 -> Clearance | B8: ='Gear Specifications'!G7 -> c | C8: ='Gear Specifications'!H7 -> 0.0067 | D8: ='Gear Specifications'!I7 -> in | E8: ='Gear Specifications'!J7 -> (0.188/P)+0.002 | F8: ='Gear Specifications'!K7 -> Table 13-3 | H8: =Variables!A7 -> Lm (Motor input shaft length) | I8: 25 | J8: =Variables!C7 -> mm | K8: =Variables!D7 -> 0.98425197 | L8: =Variables!E7 -> in | P8: hLtemp = 2*t +2*cb + OGDp) | S8: hbw= (hLmax -hL)/2
A9: ='Gear Specifications'!F8 -> Pinion Circular Pitch | B9: ='Gear Specifications'!G8 -> p(p) | C9: ='Gear Specifications'!H8 -> 0.078539816 | D9: ='Gear Specifications'!I8 -> in | E9: ='Gear Specifications'!J8 -> pi(mp) | F9: ='Gear Specifications'!K8 -> Eq 13-4 | H9: =Variables!A8 -> dm (motor input shaft diameter) | I9: 7 | J9: =Variables!C8 -> mm | K9: =Variables!D8 -> 0.27559055 | L9: =Variables!E8 -> in | P9: hLtemp | Q9: =2*L25+2*L26+C29 -> 1.0007097 | R9: in | S9: hbw | T9: =(K5-Q9)/2 -> 0.011456189 | U9: in
A10: ='Gear Specifications'!F9 -> Gear Circular Pitch | B10: ='Gear Specifications'!G9 -> p(g) | C10: ='Gear Specifications'!H9 -> 0.078539816 | D10: ='Gear Specifications'!I9 -> in | E10: ='Gear Specifications'!J9 -> pi(mg) | F10: ='Gear Specifications'!K9 -> Eq 13-4 | H10: =Variables!A9 -> ωmax (motor input speed) | I10: =Variables!B9 -> 30000 | J10: =Variables!C9 -> rpm | K10: =Variables!D9 -> 3141.5927 | L10: =Variables!E9 -> rad/s
A11: ='Gear Specifications'!F10 -> Addendum | B11: ='Gear Specifications'!G10 -> a | C11: ='Gear Specifications'!H10 -> 0.025 | D11: ='Gear Specifications'!I10 -> in | E11: ='Gear Specifications'!J10 -> 0.54/P+0.460/P(e90)^2 | F11: ='Gear Specifications'!K10 -> Table 13-3 | H11: =Variables!A10 -> Tmax (motor input torque) | I11: =Variables!B10 -> 2 | J11: =Variables!C10 -> N*cm | K11: =Variables!D10 -> 0.0147512 | L11: =Variables!E10 -> ft*lbf | P11: 3. calculate hL with hbw
A12: ='Gear Specifications'!F11 -> Dedendum | B12: ='Gear Specifications'!G11 -> b | C12: ='Gear Specifications'!H11 -> 0.028925 | D12: ='Gear Specifications'!I11 -> in | E12: ='Gear Specifications'!J11 -> 1.157/P | F12: ='Gear Specifications'!K11 -> Table 13-1 | H12: =Variables!A11 | I12: =Variables!B11 | J12: =Variables!C11 | K12: =Variables!D11 | L12: =Variables!E11 | P12: hL = 2*t +2*cb + OD(p) + hbw
A13: ='Gear Specifications'!F12 -> Whole depth | B13: ='Gear Specifications'!G12 -> ht | C13: ='Gear Specifications'!H12 -> 0.053925 | D13: ='Gear Specifications'!I12 -> in | E13: ='Gear Specifications'!J12 -> 2.157/P | F13: ='Gear Specifications'!K12 | H13: =Variables!A12 | I13: =Variables!B12 | J13: =Variables!C12 | K13: =Variables!D12 | L13: =Variables!E12 | P13: hL | Q13: =2*L25+2*L26+C29+T9 -> 1.0121659 | R13: in
A14: ='Gear Specifications'!F13 -> Pinion Pitch Cone Angle | B14: ='Gear Specifications'!G13 -> γ | C14: ='Gear Specifications'!H13 -> 0.78539816 | D14: ='Gear Specifications'!I13 -> rad | E14: ='Gear Specifications'!J13 -> tan-1(Np/Ng) | F14: ='Gear Specifications'!K13 -> Eq 13-14 | H14: =Variables!A13 | I14: =Variables!B13 | J14: =Variables!C13 | K14: =Variables!D13 | L14: =Variables!E13
A15: ='Gear Specifications'!F14 -> Gear Pitch Cone Angle | B15: ='Gear Specifications'!G14 -> Γ | C15: ='Gear Specifications'!H14 -> 0.78539816 | D15: ='Gear Specifications'!I14 -> rad | E15: ='Gear Specifications'!J14 -> tan-1(Ng/Np) | F15: ='Gear Specifications'!K14 -> Eq 13-14 | H15: =Variables!A14 -> Givens (Exact) | I15: =Variables!B14 -> value | J15: =Variables!C14 -> unit | K15: =Variables!D14 -> Conversion | L15: =Variables!E14 -> unit | P15: 4. Max lower gear bearing height = t +hbw
A16: ='Gear Specifications'!F15 -> Working depth | B16: ='Gear Specifications'!G15 -> hk | C16: ='Gear Specifications'!H15 -> 0.05 | D16: ='Gear Specifications'!I15 -> in | E16: ='Gear Specifications'!J15 -> 2/P | F16: ='Gear Specifications'!K15 -> Table 13-3 | H16: =Variables!A15 -> Dc (bur cutting surface diameter) | I16: =Variables!B15 -> 2 | J16: =Variables!C15 -> mm | K16: =Variables!D15 -> 0.078740157 | L16: =Variables!E15 -> in | Q16: =T9+L25 -> 0.090196346 | R16: in
A17: ='Gear Specifications'!F16 -> 90 Equivalent Gear Ratio | B17: ='Gear Specifications'!G16 -> e90 | C17: ='Gear Specifications'!H16 -> 1 | D17: ='Gear Specifications'!I16 -> in | E17: ='Gear Specifications'!J16 -> sqrt(e(cosγ/cosΓ) | F17: ='Gear Specifications'!K16 -> Table 13-3 | H17: =Variables!A16 -> Lc (bur cutting surface length) | I17: =Variables!B16 -> 4 | J17: =Variables!C16 -> mm | K17: =Variables!D16 -> 0.15748032 | L17: =Variables!E16 -> in
A18: ='Gear Specifications'!F17 -> Cone Distance | B18: ='Gear Specifications'!G17 -> Ao | C18: ='Gear Specifications'!H17 -> 0.83333333 | D18: ='Gear Specifications'!I17 -> in | E18: ='Gear Specifications'!J17 -> F/0.3 | F18: ='Gear Specifications'!K17 -> Table 13-3 | H18: =Variables!A17 -> Db (bur shaft diameter) | I18: =Variables!B17 -> 1.6 | J18: =Variables!C17 -> mm | K18: =Variables!D17 -> 0.062992126 | L18: =Variables!E17 -> in | P18: 5.calculate handpiece body diameter
A19: ='Gear Specifications'!F18 -> Back Cone Radius | B19: ='Gear Specifications'!G18 -> Rb | C19: ='Gear Specifications'!H18 -> 0.83333333 | D19: ='Gear Specifications'!I18 -> in | E19: ='Gear Specifications'!J18 -> Ao*tan(γ) | F19: ='Gear Specifications'!K18 | H19: =Variables!A18 -> Lb (bur total length) | I19: 34 | J19: =Variables!C18 -> mm | K19: =Variables!D18 -> 1.023622 | L19: =Variables!E18 -> in | P19: d = 2t+2*cb+ds1
A20: ='Gear Specifications'!F19 -> Addendum Angle | B20: ='Gear Specifications'!G19 -> θa | C20: ='Gear Specifications'!H19 -> 0.029991005 | D20: ='Gear Specifications'!I19 -> rad | E20: ='Gear Specifications'!J19 -> tan-1(a/Ao) | F20: ='Gear Specifications'!K19 -> SDP Table 8-3 | H20: =Variables!A19 -> Safety Factor | I20: =Variables!B19 -> 2 | J20: =Variables!C19 | K20: =Variables!D19 | L20: =Variables!E19 | P20: d | Q20: =2*L25+2*L26+J27 -> 0.44094488 | R20: in
A21: ='Gear Specifications'!F20 -> Dedendum Angle | B21: ='Gear Specifications'!G20 -> θb | C21: ='Gear Specifications'!H20 -> 0.034696071 | D21: ='Gear Specifications'!I20 -> rad | E21: ='Gear Specifications'!J20 -> tan-1(b/Ao) | F21: ='Gear Specifications'!K20 -> SDP Table 8-3
A22: ='Gear Specifications'!F21 -> Gear Angular Addendum | B22: ='Gear Specifications'!G21 -> Z (g) | C22: ='Gear Specifications'!H21 -> 0.021206843 | D22: ='Gear Specifications'!I21 -> rad | E22: ='Gear Specifications'!J21 -> θacos(Γ) | F22: ='Gear Specifications'!K21
A23: ='Gear Specifications'!F22 -> Pinion Angular Addendum | B23: ='Gear Specifications'!G22 -> Z (p) | C23: ='Gear Specifications'!H22 -> 0.021206843 | D23: ='Gear Specifications'!I22 -> rad | E23: ='Gear Specifications'!J22 -> θacos(γ) | F23: ='Gear Specifications'!K22 | H23: Input Variables | P23: 6. Minimum shaft 1 length
A24: ='Gear Specifications'!F23 -> Gear Face Angle | B24: ='Gear Specifications'!G23 -> Af (g) | C24: ='Gear Specifications'!H23 -> 0.75540716 | D24: ='Gear Specifications'!I23 -> rad | E24: ='Gear Specifications'!J23 -> Γ-θa | F24: ='Gear Specifications'!K23 -> SDP Table 8-3 | H24: Variable | I24: Symbol | J24: Value | K24: units | L24: Unit conversion | M24: Units | N24: Equation | P24: (Ls1)min = LAP+F/2+LBA
A25: ='Gear Specifications'!F24 -> Gear Root/Cutting Angle | B25: ='Gear Specifications'!G24 -> Ac (g) | C25: ='Gear Specifications'!H24 -> 0.75070209 | D25: ='Gear Specifications'!I24 -> rad | E25: ='Gear Specifications'!J24 -> Γ-θb | F25: ='Gear Specifications'!K24 -> SDP Table 8-3 | H25: Shell thickness (min) | I25: t | J25: 2 | K25: mm | L25: =J25/25.4 -> 0.078740157 | M25: in | P25: (Ls1) | Q25: =J30+J32/2+J29 -> 1.25 | R25: in
A26: ='Gear Specifications'!F25 -> Pinion Face Angle | B26: ='Gear Specifications'!G25 -> Af (p) | C26: ='Gear Specifications'!H25 -> 0.75540716 | D26: ='Gear Specifications'!I25 -> rad | E26: ='Gear Specifications'!J25 -> γ-θa | F26: ='Gear Specifications'!K25 | H26: Box clearance | I26: cb | J26: 0.1 | K26: mm | L26: =J26/25.4 -> 0.0039370079 | M26: in
A27: ='Gear Specifications'!F26 -> Pinion Root/Cutting Angle | B27: ='Gear Specifications'!G26 -> Ac (p) | C27: ='Gear Specifications'!H26 -> 0.75070209 | D27: ='Gear Specifications'!I26 -> rad | E27: ='Gear Specifications'!J26 -> γ-θb | F27: ='Gear Specifications'!K26 | H27: ='Shaft Stress Analysis'!A17 -> driving shaft diameter | I27: ='Shaft Stress Analysis'!B17 -> ds1 | J27: ='Shaft Stress Analysis'!C17 -> 0.27559055 | K27: ='Shaft Stress Analysis'!D17 -> in | N27: ='Shaft Stress Analysis'!G17 | P27: 7. Minimum shaft 2 length
A28: ='Gear Specifications'!F27 -> Gear Outside Diameter | B28: ='Gear Specifications'!G27 -> OD (g) | C28: ='Gear Specifications'!H27 -> 0.83535534 | D28: ='Gear Specifications'!I27 -> in | E28: ='Gear Specifications'!J27 -> d(g)+2(a)cosΓ | F28: ='Gear Specifications'!K27 -> SDP Table 8-3 | H28: =Variables!I19 -> distance between bearing D and gear (center to center distance) | I28: =Variables!J19 -> LDG | J28: =Variables!K19 -> 0.25 | K28: =Variables!L19 -> in | L28: =Variables!M19 | P28: (Ls2)min = LDG+LCG
A29: ='Gear Specifications'!F28 -> Pinion Outside Diameter | B29: ='Gear Specifications'!G28 -> OD (p) | C29: ='Gear Specifications'!H28 -> 0.83535534 | D29: ='Gear Specifications'!I28 -> in | E29: ='Gear Specifications'!J28 -> d(p)+2(a)cosγ | F29: ='Gear Specifications'!K28 -> SDP Table 8-3 | H29: ='Shaft Stress Analysis'!A12 -> distance between bearing B and A | I29: ='Shaft Stress Analysis'!B12 -> LBA | J29: ='Shaft Stress Analysis'!C12 -> 0.5 | K29: ='Shaft Stress Analysis'!D12 -> in | L29: ='Shaft Stress Analysis'!E12 | M29: ='Shaft Stress Analysis'!F12 | N29: ='Shaft Stress Analysis'!G12 | Q29: =J31+J32 -> 1 | R29: in
A30: ='Gear Specifications'!F29 -> Pinion Pitch Apex to Crown | B30: ='Gear Specifications'!G29 -> X(p) | C30: ='Gear Specifications'!H29 -> 0.57157798 | D30: ='Gear Specifications'!I29 -> in | E30: ='Gear Specifications'!J29 -> Aocosγ-(a)sinγ | F30: ='Gear Specifications'!K29 -> SDP Table 8-3 | H30: ='Shaft Stress Analysis'!A13 -> distance between bearing A and pinon | I30: ='Shaft Stress Analysis'!B13 -> LAP | J30: ='Shaft Stress Analysis'!C13 -> 0.5 | K30: ='Shaft Stress Analysis'!D13 -> in | L30: ='Shaft Stress Analysis'!E13 | M30: ='Shaft Stress Analysis'!F13 | N30: ='Shaft Stress Analysis'!G13
A31: ='Gear Specifications'!F30 -> Gear Pitch Apex to Crown | B31: ='Gear Specifications'!G30 -> X(g) | C31: ='Gear Specifications'!H30 -> 0.57157798 | D31: ='Gear Specifications'!I30 -> in | E31: ='Gear Specifications'!J30 -> AocosΓ-(a)sinΓ | F31: ='Gear Specifications'!K30 -> SDP Table 8-3 | H31: ='Shaft Stress Analysis'!A14 -> distance between bearing D and gear | I31: ='Shaft Stress Analysis'!B14 -> LDG | J31: ='Shaft Stress Analysis'!C14 -> 0.5 | K31: ='Shaft Stress Analysis'!D14 -> in | L31: ='Shaft Stress Analysis'!E14 | M31: ='Shaft Stress Analysis'!F14 | N31: ='Shaft Stress Analysis'!G14
A32: ='Gear Specifications'!F31 -> Large end tooth thickness | B32: ='Gear Specifications'!G31 -> tt | C32: ='Gear Specifications'!H31 -> 0.039269908 | D32: ='Gear Specifications'!I31 -> in | E32: ='Gear Specifications'!J31 -> 0.5pi/P | F32: ='Gear Specifications'!K31 | H32: ='Shaft Stress Analysis'!A15 -> distance between bearing C and gear | I32: ='Shaft Stress Analysis'!B15 -> LCG | J32: ='Shaft Stress Analysis'!C15 -> 0.5 | K32: ='Shaft Stress Analysis'!D15 -> in | L32: ='Shaft Stress Analysis'!E15 | M32: ='Shaft Stress Analysis'!F15 | N32: ='Shaft Stress Analysis'!G15
A33: ='Gear Specifications'!F32 -> Pinion small end tooth diameter | B33: ='Gear Specifications'!G32 -> td (p) | C33: ='Gear Specifications'!H32 -> 0.82495791 | D33: ='Gear Specifications'!I32 -> in | E33: ='Gear Specifications'!J32 -> 2*(Ao-F)*sin(γ) | F33: ='Gear Specifications'!K32 | H33: =Variables!I4 -> Face width | I33: =Variables!J4 -> F | J33: =Variables!K4 -> 0.25 | K33: =Variables!L4 -> in | L33: =Variables!M4 | M33: =Variables!N4
A34: ='Gear Specifications'!F33 -> Gear small end tooth diameter | B34: ='Gear Specifications'!G33 -> td (g) | C34: ='Gear Specifications'!H33 -> 0.82495791 | D34: ='Gear Specifications'!I33 -> in | E34: ='Gear Specifications'!J33 -> 2*(Ao-F)*sin(Γ) | F34: ='Gear Specifications'!K33
A35: ='Gear Specifications'!F34 -> Pinion small end tooth thickness | B35: ='Gear Specifications'!G34 -> tts (p) | C35: ='Gear Specifications'!H34 -> 0.040495027 | D35: ='Gear Specifications'!I34 -> in | E35: ='Gear Specifications'!J34 -> 0.5pi/(Np/tdp) | F35: ='Gear Specifications'!K34
A36: ='Gear Specifications'!F35 -> Gear small end tooth thickness | B36: ='Gear Specifications'!G35 -> tts (g) | C36: ='Gear Specifications'!H35 -> 0.040495027 | D36: ='Gear Specifications'!I35 -> in | E36: ='Gear Specifications'!J35 -> 0.5pi/(Ng/tdg) | F36: ='Gear Specifications'!K35

Sheet Stress Analysis of Gears
A1: Inputs | G1: Stress Analysis
A2: Variable | B2: Symbol | C2: Value | D2: Units | G2: Variable | H2: Symbol | I2: Value | J2: Units | K2: Equation | L2: Textbook Ref
A3: Speed of the pinion | B3: ω2 | C3: ='Torque&Power'!M5 -> 30000 | D3: ='Torque&Power'!N5 -> rpm | G3: Pinion bending
A4: Output Power | B4: H3 | C4: ='Torque&Power'!M7 -> 0.084258657 | D4: ='Torque&Power'!N7 -> hp | G4: Bending stress | H4: (St)P | I4: =(C20/C6)*C9*C21*C22*((C25*C27)/(C28*C29)) -> 211.6181 | J4: psi | K4: (St)P = (Wt/F)*Pd*Ko*Kv*((Ks*Km)/(Kx*JP)) | L4: Eq. 15-3
A5: Quality number | B5: Qv | C5: =Variables!K12 -> 11 | G5: Allowable bending stress | H5: (Swt)P | I5: =(C35*C36)/(C12*C38*C39) -> 6505.7621 | J5: psi | K5: (Swt)P = (Sat*(KL)P)/(SF*KT*KR) | L5: Eq. 15-4
A6: Face width | B6: F | C6: =Variables!K4 -> 0.25 | D6: in | G6: Bending factor of safety for the pinion | H6: (SF)P | I6: =((C35*C36)/(C38*C39*I4))^0.5 -> 7.8412929 | K6: (SF)P = ((Sat*(KL)P)/(KT*KR*(St)P))^0.5 | L6: Fig. 15-15
A7: Pinion pitch diameter | B7: dp | C7: ='Gear Specifications'!H5 -> 0.8 | D7: in
A8: Gear pitch diameter | B8: dg | C8: ='Gear Specifications'!H6 -> 0.8 | D8: in | G8: Gear bending
A9: Diametral Pitch | B9: Pd | C9: =Variables!K3 -> 40 | D9: teeth/in | G9: Bending stress | H9: (St)G | I9: =(C20/C6)*C9*C21*C22*((C25*C27)/(C28*C30)) -> 211.6181 | J9: psi | K9: (St)G = (Wt/F)*Pd*Ko*Kv*((Ks*Km)/(Kx*JG)) | L9: Eq. 15-3
A10: Pinion tooth number | B10: Np | C10: =Variables!K5 -> 32 | D10: teeth | G10: Allowable bending stress | H10: (Swt)G | I10: =(C35*C37)/(C12*C38*C39) -> 6505.7621 | J10: psi | K10: (Swt)G = (Sat*(KL)G)/(SF*KT*KR) | L10: Eq. 15-4
A11: Gear tooth number | B11: Ng | C11: =Variables!K6 -> 32 | D11: teeth | G11: Bending factor of safety for the gear | H11: (SF)G | I11: =((C35*C37)/(C38*C39*I9))^0.5 -> 7.8412929 | K11: (SF)G = ((Sat*(KL)G)/(KT*KR*(St)G))^0.5 | L11: Fig. 15-15
A12: Safety Number | B12: n = SF | C12: =Variables!B19 -> 2
A13: Reliability | B13: R | C13: =Variables!K14 -> 0.99 | G13: Pinion wear
A14: Life cycle of the pinion | B14: NL | C14: =Variables!K15 -> 10000000 | G14: Contact stress | H14: (Sc)P | I14: =C31*((C20/(C6*C7*C32))*C21*C22*C27*C33*C34)^0.5 -> 12700.79 | J14: psi | K14: (Sc)P = Cp*((Wt/F*dp*I)*Ko*Kv*Km*Cs*Cxc)^.5 | L14: Eq. 15-1
A15: Hardness | B15: HB | C15: =Variables!K16 -> 248 | G15: Allowable contact stress | H15: (Swc)P | I15: =(C40*C41*C43)/(C45*C38*C46) -> 71384.317 | J15: psi | K15: (Swc)P = (Sac*(CL)P*CH)/(SH*KT*CR) | L15: Eq. 15-2
A16: gear ratio | B16: mG | C16: =Variables!K13 -> 1 | G16: Wear factor of safety for the pinion | H16: (SH)P | I16: =((C40*C41*C43)/(C38*C46*I14))^0.5 -> 3.352749 | K16: (SH)P= ((Sac*(CL)P*CH)/(KT*CR*(Sc)P))^0.5 | L16: Fig. 15-14
A18: Needed Variables | B18: Symbol | C18: Value | D18: units | E18: Equation | G18: Gear wear
A19: Pitch line velocity | B19: V | C19: =(pi()*C7*C3)/12 -> 6283.1853 | D19: ft/min | E19: V = pi *d*n/12 | G19: Contact stress | H19: (Sc)G | I19: =C31*((C20/(C6*C7*C32))*C21*C22*C27*C33*C34)^0.5 -> 12700.79 | J19: psi | K19: (Sc)G = Cp*((Wt/F*dp*I)*Ko*Kv*Km*Cs*Cxc)^.5 | L19: Eq. 15-1
A20: Transmitted Load | B20: Wt | C20: =33000*(C4/C19) -> 0.442536 | D20: lbf | E20: Wt = 33000 * H/V | G20: Allowable contact stress | H20: (Swc)G | I20: =(C40*C42*C43)/(C45*C38*C46) -> 71384.317 | J20: psi | K20: (Swc)G = (Sac*(CL)G*CH)/(SH*KT*CR) | L20: Eq. 15-2
A21: Overload Factors | B21: Ko | C21: 1 | E21: Table 15-2 | G21: Wear factor of safety fot the gear | H21: (SH)G | I21: =((C40*C42*C43)/(C38*C46*I19))^0.5 -> 3.352749 | K21: (SH)G= ((Sac*(CL)G*CH)/(KT*CR*(Sc)G))^0.5 | L21: Fig. 15-14
A22: Dynamic Factors | B22: Kv | C22: =((C23+SQRT(C19))/C23)^C24 -> 1.1680762 | E22: Kv = (A+(SQRT(V))/A)^B
B23: A | C23: =50+56*(1-C24) -> 92 | E23: Eq. 15-6, A = 50 +56(1-B)
B24: B | C24: =0.25*(12-C5)^(2/3) -> 0.25 | E24: Eq. 15-6, B = 0.25(12-Qv)^(2/3)
A25: Size factor | B25: Ks | C25: 0.5 | E25: 15-10, Pd>16 teeth/in
A26: Kmb- needed for Km | B26: Kmb | C26: 1.1 | E26: one member straddle mounted
A27: Load distribution factor | B27: Km | C27: =C26+0.0036*(C6^2) -> 1.100225 | E27: Km = Kmb+0.0036*F^2
A28: Lengthwise curvature factor | B28: Kx | C28: 1 | E28: 15-13
A29: Geometry factor for Pinion | B29: (J)P | C29: 0.215 | E29: Fig. 15-7
A30: Geometry Factor for Gear | B30: (J)G | C30: 0.215 | E30: Fig. 15-7
A31: Elastic Coefficient | B31: Cp | C31: 2290 | D31: psi^0.5 | E31: 15-21, assume steel
A32: Geometry factor for pitting resistance | B32: I | C32: 0.065 | E32: Fig. 15-6
A33: Size factor for piting resistance | B33: Cs | C33: =(0.125*C6)+0.4375 -> 0.46875 | E33: Cs = 0.125F+0.4375
A34: Crowning factor for pitting resistance | B34: Cxc | C34: 1.5 | E34: 15-12
A35: Allowable bending stress number | B35: Sat | C35: =(44*C15)+2100 -> 13012 | D35: psi | E35: Sat = 44(HB)+2100 psi
A36: Pinion Stress Cycle Factor for bending strength | B36: (KL)P | C36: =1.683*(C14)^-0.0323 -> 0.99996343 | E36: 1.683NL^-0.0323
A37: Gear Stress Cycle Factor for bending strength | B37: (KL)G | C37: =1.683*(C14/C16)^-0.0323 -> 0.99996343 | E37: 1.683(NL/mG)^-.0323
A38: Temperature Factor | B38: KT | C38: 1 | E38: 15-18, assume t<250 degrees
A39: Reliability Factor | B39: KR | C39: =0.5-0.25*log(1-C13) -> 1 | E39: 0.50-0.25log(1-R)
A40: Allowable contact stress number for steel gears | B40: Sac | C40: =(341*C15)+23620 -> 108188 | D40: psi | E40: Sac = 341(HB)+23620 psi
A41: Pinion Stress-Cycle Factor for pitting resistance | B41: (CL)P | C41: =3.4822*(C14)^-0.0602 -> 1.3196347 | E41: 3.4822NL^-0.0602
...

Sheet Shaft Stress Analysis
A2: Inputs | I2: Shaft Outputs - For Driving Shaft | S2: Shaft Outputs - For Driven Shaft
A3: Variable | B3: Symbol | C3: Value | D3: Units | E3: Unit conversion | F3: Units | G3: Textbook Ref | I3: Variable | J3: Symbol | K3: Value | L3: Units | M3: Unit conversion | N3: Units | O3: Equation | P3: Textbook Ref | S3: Variable | T3: Symbol | U3: Value | V3: Units | W3: Unit conversion | X3: Units | Y3: Equation | Z3: Textbook Ref
A4: Speed of the pinion | B4: ω2 | C4: ='Torque&Power'!M5 -> 30000 | D4: ='Torque&Power'!N5 -> rpm | I4: Radial Force | J4: Wr | K4: =C8*tan(E9)*cos(C20) -> 0.11389364 | L4: lbf | O4: (Wt)tanΦcosΓ | P4: Eq 13-38 | S4: Radial Force | T4: Wr | U4: =C8*tan(E9)*cos(C20) -> 0.11389364 | V4: lbf | Y4: (Wt)tanΦcosΓ | Z4: Eq 13-38
A5: speed of gear | B5: ω3 | C5: =Variables!K10 -> 30000 | D5: =Variables!L10 -> rpm | I5: Axial Force | J5: Wa | K5: =C8*tan(E9)*cos(C20) -> 0.11389364 | L5: lbf | O5: (Wt)tanΦsinΓ | P5: Eq 13-38 | S5: Axial Force | T5: Wa | U5: =C8*tan(E9)*cos(C20) -> 0.11389364 | V5: lbf | Y5: (Wt)tanΦsinΓ | Z5: Eq 13-38
A6: torque of pinon | B6: ='Torque&Power'!G9 -> T2 | C6: ='Torque&Power'!H9 -> 0.0147512 | D6: ='Torque&Power'!I9 -> ft*lbf | I6: Magnitude of non-axial load | J6: Wtr | K6: =sqrt(C8^2+K4^2) -> 0.45695719 | L6: =L4 -> lbf | O6: sqrt(Wt^2+Wr^2) | S6: Magnitude of non-axial load | T6: Wra | U6: =sqrt(U5^2+U4^2) -> 0.16106993 | V6: =V4 -> lbf | Y6: sqrt(Wa^2+Wr^2)
A7: torque of gear | B7: T3 | C7: ='Torque&Power'!M6 -> 0.0147512 | D7: ='Torque&Power'!N6 -> ft*lbf | I7: Reaction Force from bearing B | J7: Rb | K7: =K6*C13/C12 -> 0.45695719 | L7: =L6 -> lbf | O7: Wtr*LAP/LAB | S7: Reaction Force from bearing D | T7: Rd | U7: =U6*C15/(C14+C15) -> 0.080534966 | V7: =V6 -> lbf | Y7: Wra*LCG/(LCG+LDG) | Z7: table A-9-6
A8: transmitted load | B8: Wt | C8: ='Stress Analysis of Gears'!C20 -> 0.442536 | D8: ='Stress Analysis of Gears'!D20 -> lbf | I8: Reaction Force from bearing A | J8: Ra | K8: =K6*(C12+C13)/C12 -> 0.91391438 | L8: =L6 -> lbf | O8: Wtr*(LBA+LAP)/LBA | S8: Reaction Force from bearing C | T8: Rc | U8: =U6*C14/(C14+C15) -> 0.080534966 | V8: =V6 -> lbf | Y8: Wra*LDG/(LCG+LDG) | Z8: table A-9-6
A9: pressure angle | B9: Φp | C9: =Variables!K7 -> 20 | D9: =Variables!L7 -> degrees | E9: =Variables!M7 -> 0.34906585 | F9: =Variables!N7 -> rad | I9: Max Momment (momment at A) | J9: Mmax | K9: =-K6*C13*C12/C12 -> -0.22847859 | L9: lbf*in | O9: -Wtr*LAP*LBA/LBA | S9: Max Momment (momment at A) | T9: Mmax | U9: =U6*C15*C14/(C14+C15) -> 0.040267483 | V9: lbf*in | Y9: Wra*LCG*LDG/(LCG+LDG) | Z9: table A-9-6
A10: ='Gear Specifications'!F5 -> Pinion Pitch Diameter | B10: ='Gear Specifications'!G5 -> d(p) | C10: ='Gear Specifications'!H5 -> 0.8 | D10: ='Gear Specifications'!I5 -> in | I10: alternating Moment | J10: Ma | K10: =ABS(K9-(-K9))/2 -> 0.22847859 | L10: lbf*in | O10: |Mmax-(Mmax)|/2 | S10: alternating Moment | T10: Ma | U10: =ABS(U9-(-U9))/2 -> 0.040267483 | V10: lbf*in | Y10: |Mmax-(-Mmax)|/2
A11: ='Gear Specifications'!F6 -> Gear Pitch Diameter | B11: ='Gear Specifications'!G6 -> d(g) | C11: ='Gear Specifications'!H6 -> 0.8 | D11: ='Gear Specifications'!I6 -> in | I11: mean Moment | J11: Mm | K11: 0 | L11: lbf*in | O11: 0 for complety reversed bending load and constant torsion | S11: mean Moment | T11: Mm | U11: 0 | V11: lbf*in | Y11: 0 for completely reversed bending load and constant torsion
A12: distance between bearing B and A | B12: LBA | C12: 0.5 | D12: in | I12: alternating Torque | J12: Ta | K12: 0 | L12: =D6 -> ft*lbf | M12: =K12*12 -> 0 | N12: in*lbf | O12: 0 for complety reversed bending load and constant torsion | S12: alternating Torque | T12: Ta | U12: 0 | V12: =D6 -> ft*lbf | W12: =U12*12 -> 0 | X12: in*lbf | Y12: 0 for completely reversed bending load and constant torsion
A13: distance between bearing A and pinon | B13: LAP | C13: 0.5 | D13: in | I13: Mean Torque | J13: Tm | K13: =C6 -> 0.0147512 | L13: =D6 -> ft*lbf | M13: =K13*12 -> 0.1770144 | N13: in*lbf | O13: T2 | S13: Mean Torque | T13: Tm | U13: =C7 -> 0.0147512 | V13: =D7 -> ft*lbf | W13: =U13*12 -> 0.1770144 | X13: in*lbf | Y13: T3
A14: distance between bearing D and gear | B14: LDG | C14: 0.5 | D14: in | I14: surface factor | J14: ka | K14: =C23*C19^C24 -> 0.4896941 | O14: ka=aSut^b | P14: 45095 | S14: surface factor | T14: ka | U14: =C23*C19^C24 -> 0.4896941 | Y14: ka=aSut^b | Z14: 45095
A15: distance between bearing C and gear | B15: LCG | C15: 0.5 | D15: in | I15: size factor | J15: kb | K15: 1 | O15: kb=1 | P15: see pg. 312 | S15: size factor | T15: kb | U15: 1 | Y15: kb=1 | Z15: 45097
A16: safety factor | B16: n | C16: =Variables!B19 -> 2 | I16: load factor | J16: kc | K16: 1 | O16: kc=1 | P16: see pg. 314 | S16: load factor | T16: kc | U16: 1 | Y16: kc=1 | Z16: for torsion in combination with other loading (pg.314)
A17: driving shaft diameter | B17: ds1 | C17: =7/25.4 -> 0.27559055 | D17: in | I17: temperature factor | J17: kd | K17: 1 | O17: kd=1 | P17: see pg.316 | S17: temperature factor | T17: kd | U17: 1 | Y17: kd=` | Z17: see pg.316
A18: driven shaft diameter | B18: ds2 | C18: =Variables!D17 -> 0.062992126 | D18: in | I18: reliability factor | J18: ke | K18: 0.868 | O18: 0.868 for 95% reliablity | P18: table 6-4 | S18: reliability factor | T18: ke | U18: 0.814 | Y18: 0.814 for 99% reliablity | Z18: table 6-4
A19: Tensile strength | B19: Sut | C19: 120 | D19: Kpsi | E19: =C19*1000 -> 120000 | F19: psi | G19: table A-20 | I19: endurance limit of rotary-beam specimen | J19: S'e | K19: =0.5*C19 -> 60 | L19: =D19 -> Kpsi | M19: =K19*1000 -> 60000 | N19: psi | P19: 45111 | S19: endurance limit of rotary-beam specimen | T19: S'e | U19: =0.5*C19 -> 60 | V19: =D19 -> Kpsi | W19: =U19*1000 -> 60000 | X19: psi | Z19: 45111
A20: ='Gear Specifications'!F14 -> Gear Pitch Cone Angle | B20: ='Gear Specifications'!G14 -> Γ | C20: ='Gear Specifications'!H14 -> 0.78539816 | D20: ='Gear Specifications'!I14 -> rad | I20: endurance limit | J20: Se | K20: =K14*K15*K16*K17*K18*K19 -> 25.503269 | L20: =L19 -> Kpsi | M20: =K20*1000 -> 25503.269 | N20: psi | O20: ka*kb*kc*kd*ke*S'e | P20: 45094 | S20: endurance limit | T20: Se | U20: =U14*U15*U16*U17*U18*U19 -> 23.91666 | V20: =V19 -> Kpsi | W20: =U20*1000 -> 23916.66 | X20: psi | Y20: ka*kb*kc*kd*ke*S'e | Z20: 45094
B21: Kf | C21: 1 | I21: Alternating stress | J21: σa | K21: =C21*32*K10/(PI()*C17^3) -> 111.18665 | L21: psi | O21: Kf*32*Ma/(pi*ds^3) | P21: 45109 | T21: σa | U21: =C21*32*U10/(PI()*C18^3) -> 1640.9517 | V21: psi | Y21: Kf*32*Ma/(pi*ds^3) | Z21: 45109
B22: Kfs | C22: 1 | I22: Mean stress | J22: σm | K22: =C21*32*K11/(PI()*C17^3) -> 0 | L22: psi | O22: Kf*32*Mm/(pi*ds^3) | P22: 45109 | T22: σm | U22: =C211*32*U11/(PI()*C18^3) -> 0 | V22: psi | Y22: Kf*32*Mm/(pi*ds^3) | Z22: 45109
A23: Factor a (for ka) | B23: a | C23: 11 | G23: Table 6-2 | I23: Alternating Torsion | J23: τa | K23: =C22*16*K12/(PI()*C17^3) -> 0 | L23: psi | O23: Kfs*16*Ta/(pi*ds^3) | P23: 45110 | T23: τa | U23: =C22*16*U12/(PI()*C18^3) -> 0 | V23: psi | Y23: Kfs*16*Ta/(pi*ds^3) | Z23: 45110
A24: exponent b (for ka) | B24: b | C24: -0.65 | G24: Table 6-2 | I24: Mean Torsion | J24: τm | K24: =C22*16*M13/(PI()*C17^3) -> 43.071078 | L24: psi | O24: Kfs*16*Tm/(pi*ds^3) | P24: 45110 | T24: τm | U24: =C22*16*W13/(PI()*C18^3) -> 3606.7821 | V24: psi | Y24: Kfs*16*Tm/(pi*ds^3) | Z24: 45110
A25: =Variables!A8 -> dm (motor input shaft diameter) | B25: 25 | C25: =Variables!C8 -> mm | D25: =Variables!D8 -> 0.27559055 | E25: =Variables!E8 -> in | F25: =Variables!F8 | I25: Alternating von Mises stress | J25: σ'a | K25: =SQRT(K21^2+3*K23^2) -> 111.18665 | L25: psi | O25: (σa^2+ 3*τa^2)^(1/2) | P25: 45111 | T25: σ'a | U25: =SQRT(U21^2+3*U23^2) -> 1640.9517 | V25: psi | Y25: (σa^2+ 3*τa^2)^(1/2) | Z25: 45111
I26: Mean von Mises Stress | J26: σ'm | K26: =SQRT(K22^2+3*K24^2) -> 74.601295 | L26: psi | O26: (σm^2+ 3*τm^2)^(1/2) | P26: 45112 | T26: σ'm | U26: =SQRT(U22^2+3*U24^2) -> 6247.1299 | V26: psi | Y26: (σm^2+ 3*τm^2)^(1/2) | Z26: 45112
I30: 1. Does Shaft fail DE-Goodman Criteria? | S30: 1. Does Shaft fail DE-Goodman Criteria?
I31: σ'a/Se + σ'm/Sut | J31: =K25/M20+K26/E19 -> 0.0049813794 | S31: σ'a/Se + σ'm/Sut | T31: =U25/W20+U26/E19 -> 0.12067065
I35: 2. Actual safety factor | S35: 2. Actual safety factor
I36: n = 1/(σ'a/Se + σ'm/Sut) | J36: =1/J31 -> 200.74761 | S36: n = 1/(σ'a/Se + σ'm/Sut) | T36: =1/T31 -> 8.2870189

Sheet Mass
A1: Specifications | F1: Volume Outputs
A2: Gear Material | B2: AISI 1095 | F2: Name | G2: Symbol | H2: Value | I2: Unit
A3: Shaft Material | B3: AISI 1095 | F3: Bur driven shaft length | G3: Ldr | H3: =C29-C27 -> 1.8115197 | I3: in
A4: Shell Material | B4: stainless steel 316 | F4: Handpiece larger radius | G4: R | H4: =0.5*C21 -> 0.39370079 | I4: in
A5: Bearing Material | B5: chrome steel | F5: Handpiece smaller radius | G5: r | H5: =0.5*(C21-(2*C31)) -> 0.31496063 | I5: in
A6: Burr Material | B6: tungsten carbide | F6: Head larger radius | G6: Rh | H6: =0.5*C19 -> 0.43307087 | I6: in
A7: Bearing Type | B7: No. 602, Miniature ball bearing | F7: Head smaller radius | G7: rh | H7: =0.5*(C19-(2*C31)) -> 0.35433071 | I7: in
F8: Height of bearing D wall | G8: hbwd | H8: 0.216 | I8: in
F9: Outer diameter of bearing CD hole | H9: =H10+C31 -> 0.35874016 | I9: in
A10: Input Variable | F10: Inner diameter of bearing CD hole | H10: =C34 -> 0.28 | I10: in
A11: Name | B11: Symbol | C11: Value | D11: Unit | F11: Bearing CD hole larger radius | H11: =0.5*H9 -> 0.17937008 | I11: in
A12: Gear Material Density | B12: ρg | C12: 0.284 | D12: lb/in3 | F12: Bearing CD hole smaller radius | H12: =0.5*(H9-(2*C31)) -> 0.10062992 | I12: in
A13: Shaft Material Density | B13: ρs | C13: 0.284 | D13: lb/in3 | F13: Bearing D Hole Volume | G13: Vhd | H13: =pi()*(H11^2-H12^2)*H8 -> 0.014960907 | I13: in3
A14: Shell material Density | B14: ρsh | C14: 0.288 | D14: lb/in3 | F14: Bearing C Hole Volume | G14: Vhc | H14: =pi()*(H9^2-H10^2)*C39 -> 0.0018101332 | I14: in3
A15: Bearing material Density | B15: ρbe | C15: 0.2835 | D15: lb/in3 | F15: Total Head Shell Volume | G15: Vhe | H15: =(pi()*(H6^2-H7^2)*C20)+2*(pi()*H7^2*C31)+H13+H14 -> 0.27826586 | I15: in3
A16: Burr material Density | B16: ρbu | C16: 0.567 | D16: lb/in3 | F16: Total Handle Shell Volume | G16: Vha | H16: =(pi()*(H4^2-H5^2)*C22)+(pi()*H5^2*C31) -> 0.71470139 | I16: in3
A17: Shell thickness | B17: t | C17: ='Geometry checks'!L25 -> 0.078740157 | D17: in | F17: Driven Shaft Volume | G17: Vdr | H17: =(pi()*(0.5*C28)^2*C30) -> 0.0056455398 | I17: in3
A18: total handpiece length | B18: Lt | C18: 4.8031496 | D18: in | F18: Driving Shaft Volume | G18: Vd | H18: =(pi()*(0.5*C24)^2*C25) -> 0.17613541 | I18: in3
A19: head diameter | B19: dh | C19: 0.86614173 | D19: in | F19: Bearing A Volume | G19: Vba | H19: =pi()*((0.5*C32)^2-(0.5*C33)^2)*C36 -> 0.027719506 | I19: in3
A20: head height | B20: hL | C20: 1.023622 | D20: in | F20: Bearing B Volume | G20: Vbb | H20: =H19 -> 0.027719506 | I20: in3
A21: handpiece body diameter | B21: d | C21: 0.78740157 | D21: in | F21: Bur volume | G21: Vb | H21: =pi()*(0.5*C26)^2*C27 -> 0.00076684698 | I21: in3
A22: handpiece body length | B22: L | C22: 3.9370079 | D22: in | F22: Motor input shaft volume | G22: Vm | H22: =pi()*(0.5*C24)^2*C23 -> 0.058711722 | I22: in3
A23: Motor input shaft length | B23: Lm | C23: 0.98425197 | D23: in | F23: Pinion volume | G23: Vp | H23: =(pi()*((0.5*C44)^2-(0.5*C24)^2)*C46)+C52*(0.5*(C50+C49)*(C47+C48)*C46) -> 0.12795623 | I23: in3
A24: motor input shaft diameter | B24: dm | C24: 0.27559055 | D24: in | F24: Gear volume | G24: Vg | H24: =(pi()*((0.5*C45)^2-(0.5*C28)^2)*C46)+C53*(0.5*(C51+C49)*(C47+C48)*C46) -> 0.14208989 | I24: in3
A25: Driving shaft length | B25: Ls1 | C25: 2.95276 | D25: in
A26: bur cutting surface diameter | B26: Dc | C26: =Variables!D15 -> 0.078740157 | D26: in
A27: bur cutting surface length | B27: Lc | C27: =Variables!D16 -> 0.15748032 | D27: in | F27: Mass Outputs
A28: bur (driven) shaft diameter | B28: Db | C28: ='Shaft Stress Analysis'!C18 -> 0.062992126 | D28: in | F28: Name | G28: Symbol | H28: Value | I28: Unit | J28: Conversion | K28: Unit
A29: bur total length | B29: Lb | C29: 1.969 | D29: in | F29: Headpiece Mass | G29: mhe | H29: =H15*C14 -> 0.080140568 | I29: lb | J29: =H29*453.6 -> 36.351762 | K29: g
A30: Driven shaft length | B30: Ls2 | C30: =C29-C27 -> 1.8115197 | D30: in | F30: Handpiece mass | G30: mha | H30: =H16*C14 -> 0.205834 | I30: lb | J30: =H30*453.6 -> 93.366303 | K30: g
A31: Shell thickness | B31: t | C31: ='Geometry checks'!L25 -> 0.078740157 | D31: in | F31: Driving shaft mass | G31: md | H31: =H18*C13 -> 0.050022457 | I31: lb | J31: =H31*453.6 -> 22.690186 | K31: g
A32: A&B Outer bearing diameter | B32: ODb (AB) | C32: =C21-(2*C31) -> 0.62992126 | D32: in | F32: Driven shaft mass | G32: mdr | H32: =H17*C13 -> 0.0016033333 | I32: lb | J32: =H32*453.6 -> 0.72727198 | K32: g
A33: A&B Inner bearing diameter | B33: Bd (AB) | C33: =C24 -> 0.27559055 | D33: in | F33: Burr mass | G33: mb | H33: =H21*C16 -> 0.00043480224 | I33: lb | J33: =H33*453.6 -> 0.1972263 | K33: g
A34: C&D Outer bearing diameter | B34: ODb (CD) | C34: 0.28 | D34: in | F34: Motor input shaft mass | G34: mm | H34: =H22*C13 -> 0.016674129 | I34: lb | J34: =H34*453.6 -> 7.563385 | K34: g
A35: C&D Inner bearing diameter | B35: Bd (CD) | C35: =C28 -> 0.062992126 | D35: in | F35: Pinion mass | G35: mp | H35: =H23*C12 -> 0.036339568 | I35: lb | J35: =H35*453.6 -> 16.483628 | K35: g
A36: A&B Bearing thickness | B36: Bab | C36: 0.11 | D36: in | F36: Gear mass | G36: mg | H36: =H24*C12 -> 0.040353528 | I36: lb | J36: =H36*453.6 -> 18.30436 | K36: g
A37: C&D Bearing thickness | B37: Bcd | C37: 0.11 | D37: in | F37: Bearing A mass | G37: mba | H37: =H19*C15 -> 0.0078584798 | I37: lb | J37: =H37*453.6 -> 3.5646064 | K37: g
A38: Box clearance | B38: cb | C38: ='Geometry checks'!L26 -> 0.0039370079 | D38: in | F38: Bearing B mass | G38: mbb | H38: =H20*C15 -> 0.0078584798 | I38: lb | J38: =H38*453.6 -> 3.5646064 | K38: g
A39: Height of bearing c wall | B39: hbw | C39: ='Geometry checks'!X4 -> 0.011456189 | D39: in | F39: Bearing C mass | G39: mbc | H39: =J39/453.6 -> 0.0011022928 | I39: lb | J39: 0.5 | K39: g
A40: distance between bearing B and A | B40: LBA | C40: 0.1 | D40: in | F40: Bearing D mass | G40: mbd | H40: =J40/453.6 -> 0.0011022928 | I40: lb | J40: 0.5 | K40: g
...

Sheet Sheet1

Sheet checking stuff
B2: Inputs | I2: Torque/Power Calculation Outputs
B3: Variable | C3: Symbol | D3: Value | E3: Units | F3: Conversion | G3: unit | I3: Variable | J3: Symbol | K3: Value | L3: Units | M3: Equation | N3: Textbook Ref
B4: ='Gear Specifications'!F5 -> Pinion Pitch Diameter | C4: ='Gear Specifications'!G5 -> d(p) | D4: ='Gear Specifications'!H5 -> 0.8 | E4: ='Gear Specifications'!I5 -> in | I4: transmitted load(pinon)max | J4: (Wt)max | K4: =2*F5/D4 -> 0.442536 | L4: lbf | M4: Tmax/rav = 2Tmax/dav | N4: (13-37)
B5: max input torque | C5: Tmax | D5: =Variables!D10 -> 0.0147512 | E5: =Variables!E10 -> ft*lbf | F5: =D5*12 -> 0.1770144 | G5: in*lbf | I5: transmitted load | J5: Wt | K5: =2*F6/D4 -> 0.442536 | L5: lbf | M5: T/rav = 2T/dav | N5: (13-37)
B6: input torque | C6: T2 | D6: =D5 -> 0.0147512 | E6: =E5 -> ft*lbf | F6: =D6*12 -> 0.1770144 | G6: in*lbf | I6: Pitch-line velcocity | J6: V | K6: =pi()*D4*D8/12 -> 6283.1853 | L6: ft/min
B7: max input speed | C7: n2max | D7: =Variables!B9 -> 30000 | E7: =Variables!C9 -> rpm | I7: Max Power | J7: Hmax | K7: =K4*K6/33000 -> 0.084258657 | L7: hp
B8: input speed | C8: n2 | D8: =D7 -> 30000 | E8: rpm | I8: Power | J8: H | K8: =K5*K6/33000 -> 0.084258657 | L8: hp
B9: output speed | C9: n3 | D9: =Variables!K10 -> 30000 | E9: =Variables!L10 -> rpm | I9: input angular velocity | J9: ω2 | K9: =K8*33000/(D6*2*PI()) -> 30000 | L9: rpm | M9: H*33000/(T*2*pi)
B10: =Variables!I5 -> Pinion tooth | C10: =Variables!J5 -> Np = N2 | D10: =Variables!K5 -> 32 | E10: =Variables!L5 -> teeth | I10: gear train ration | J10: e | K10: =D10/D11 -> 1 | M10: N2/N3 = ω3/ω2
B11: =Variables!I6 -> Gear tooth | C11: =Variables!J6 -> Ng = N3 | D11: =Variables!K6 -> 32 | E11: =Variables!L6 -> teeth | I11: output angular velocity | J11: ω3 | K11: =K9*K10 -> 30000 | L11: rpm | M11: e*ω2
I12: output torque | J12: T3 | M12: H*33000/(ω2*2*pi)

Sheet Gear Bearing Force Analysis
A1: Inputs | H1: Force Analysis
A2: Variable | B2: Symbol | C2: Value | D2: Units | E2: Conversion | F2: unit | H2: Variable | I2: Symbol | J2: Value | K2: Units | L2: Equation | M2: Textbook Ref
A3: Pinion Pitch Cone Angle | B3: γ | C3: ='Gear Specifications'!H13 -> 0.78539816 | D3: rad | H3: Radial Force | I3: Wr | J3: =C6*tan(C7)*cos(C4) -> 0.11389364 | K3: lbf | L3: (Wt)tanΦcosΓ | M3: Eq 13-38
A4: Gear Pitch Cone Angle | B4: Γ | C4: ='Gear Specifications'!H14 -> 0.78539816 | D4: rad | H4: Axial Force | I4: Wa | J4: =C6*tan(C7)*sin(C4) -> 0.11389364 | K4: lbf | L4: (Wt)tanΦsinΓ | M4: Eq 13-38
A5: Pitch Line Velocity | B5: V | C5: ='Stress Analysis of Gears'!C19 -> 6283.1853 | D5: ft/min | H5: Bearing B to Bearing A | I5: LBA | J5: 1 | K5: in
A6: Transmitted Load | B6: Wt | C6: ='Stress Analysis of Gears'!C20 -> 0.442536 | D6: lbf | H6: Bearing A to Pinion 1/2 Face | I6: LAP | J6: 1 | K6: in
A7: Pressure angle | B7: Φp | C7: =Variables!M7 -> 0.34906585 | D7: rad | H7: Bearing D to Gearing 1/2 Face | I7: LDG | J7: 1 | K7: in
A8: Face width | B8: F | C8: =Variables!K4 -> 0.25 | D8: =Variables!L4 -> in | H8: Bearing C to Geaing 1/2 Face | I8: LCG | J8: 1 | K8: in
A9: ='Gear Specifications'!F29 -> Pinion Pitch Apex to Crown | B9: ='Gear Specifications'!G29 -> X(p) | C9: ='Gear Specifications'!H29 -> 0.57157798 | D9: ='Gear Specifications'!I29 -> in | H9: Gear 1/2 Face to Pitch Apex | I9: Xo (g) | J9: =C10-(0.5*C8) -> 0.44657798 | K9: in | L9: X(g)-1/2F | M9: Ex 13-8
A10: ='Gear Specifications'!F30 -> Gear Pitch Apex to Crown | B10: ='Gear Specifications'!G30 -> X(g) | C10: ='Gear Specifications'!H30 -> 0.57157798 | D10: ='Gear Specifications'!I30 -> in | H10: Pinion 1/2 Face to Pitch Apex | I10: Xo (p) | J10: =C9-(0.5*C8) -> 0.44657798 | K10: in | L10: X(p)-1/2F | M10: Ex 13-8
A11: Torque of driven shaft | B11: T3 = Ts3 | C11: ='Torque&Power'!M6 -> 0.0147512 | D11: ='Torque&Power'!N6 -> ft*lbf | E11: =C11*12 -> 0.1770144 | F11: in*lbf
H15: Gear Vectors
H16: Variable | I16: Symbol | J16: i | K16: j | L16: k | M16: Units | N16: Notes
A17: Answer | B17: Symbol | C17: Value | D17: Units | H17: Position vector from D to E | I17: RDE | J17: =J10 -> 0.44657798 | K17: =-J7 -> -1 | L17: =0 -> 0 | M17: =K7 -> in
A18: Force from Bearing A | B18: Fa | C18: =SQRT(J31^2+K31^2+L31^2) -> 0 | D18: =M31 | H18: Position vector from D to C | I18: RDC | J18: 0 | K18: =-(J7+J8) -> -2 | L18: 0 | M18: =K8 -> in
A19: Force from Bearing B | B19: Fb | C19: =SQRT(J32^2+K32^2+L32^2) -> 0 | D19: =M32 | H19: Load vector | I19: W | J19: =-J3 -> -0.11389364 | K19: =-J4 -> -0.11389364 | L19: =C6 -> 0.442536 | M19: =D6 -> lbf
A20: Force from Bearing C | B20: Fc | C20: =sqrt(J22^2+K22^2+L22^2) -> 0.26775993 | D20: =M22 -> lbf | H20: Torque | I20: T | J20: =0 -> 0 | K20: =0 -> 0 | L20: =E11 -> 0.1770144 | M20: lbf*in
A21: Force from Bearing D | B21: Fd | C21: =sqrt(J23^2+K23^2+L23^2) -> 0.22178129 | D21: =M23 -> lbf | H21: (Cross product of RDE and W)+T | I21: (RDE x W)+T | J21: =(K17*L19-L17*K19)+J20 -> -0.442536 | K21: =(L17*J19-J17*L19)+K20 -> -0.19762683 | L21: =(J17*K19-K17*J19)+L20 -> 0.012258367 | N21: (RDE x W)+T
A22: Force between gears | B22: F32 | C22: =sqrt(C6^2+J3^2+J4^2) -> 0.47093697 | D22: =D6 -> lbf | H22: Force from Bearing C Vector | I22: Fc | J22: =K21/K18 -> 0.098813417 | K22: =-K19 -> 0.11389364 | L22: =-J21/K18 -> -0.221268 | M22: lbf
H23: Force from Bearing D Vector | I23: Fd | J23: =(J19+J22) -> -0.015080224 | K23: 0 | L23: =-(L19+L22) -> -0.221268 | M23: lbf
A24: Looking at textbook ex 13-8
H25: Pinion Vectors
H26: Variable | I26: Symbol | J26: i | K26: j | L26: k | M26: Units | N26: Notes
H27: Position of A to E
H28: Position of A to B
H29: Torque
H30: (Cross product of RAE and W)+T
H31: Force from Bearing A Vector
H32: Force from Bearing B Vector
